[2024-04-13T14:44:13.834+0000] {taskinstance.py:1083} INFO - Dependencies all met for <TaskInstance: challenge_dag.transform_task manual__2024-04-13T14:44:08.039820+00:00 [queued]>
[2024-04-13T14:44:13.839+0000] {taskinstance.py:1083} INFO - Dependencies all met for <TaskInstance: challenge_dag.transform_task manual__2024-04-13T14:44:08.039820+00:00 [queued]>
[2024-04-13T14:44:13.840+0000] {taskinstance.py:1279} INFO - 
--------------------------------------------------------------------------------
[2024-04-13T14:44:13.840+0000] {taskinstance.py:1280} INFO - Starting attempt 1 of 1
[2024-04-13T14:44:13.840+0000] {taskinstance.py:1281} INFO - 
--------------------------------------------------------------------------------
[2024-04-13T14:44:13.870+0000] {taskinstance.py:1300} INFO - Executing <Task(PythonOperator): transform_task> on 2024-04-13 14:44:08.039820+00:00
[2024-04-13T14:44:13.874+0000] {standard_task_runner.py:55} INFO - Started process 20188 to run task
[2024-04-13T14:44:13.877+0000] {standard_task_runner.py:82} INFO - Running: ['airflow', 'tasks', 'run', 'challenge_dag', 'transform_task', 'manual__2024-04-13T14:44:08.039820+00:00', '--job-id', '30', '--raw', '--subdir', 'DAGS_FOLDER/challenge_dag.py', '--cfg-path', '/tmp/tmp76badc7o']
[2024-04-13T14:44:13.878+0000] {standard_task_runner.py:83} INFO - Job 30: Subtask transform_task
[2024-04-13T14:44:13.931+0000] {task_command.py:388} INFO - Running <TaskInstance: challenge_dag.transform_task manual__2024-04-13T14:44:08.039820+00:00 [running]> on host codespaces-3318c7
[2024-04-13T14:44:14.108+0000] {taskinstance.py:1507} INFO - Exporting the following env vars:
AIRFLOW_CTX_DAG_OWNER=airflow
AIRFLOW_CTX_DAG_ID=challenge_dag
AIRFLOW_CTX_TASK_ID=transform_task
AIRFLOW_CTX_EXECUTION_DATE=2024-04-13T14:44:08.039820+00:00
AIRFLOW_CTX_TRY_NUMBER=1
AIRFLOW_CTX_DAG_RUN_ID=manual__2024-04-13T14:44:08.039820+00:00
[2024-04-13T14:44:14.113+0000] {taskinstance.py:1768} ERROR - Task failed with exception
Traceback (most recent call last):
  File "/usr/local/python/3.10.13/lib/python3.10/site-packages/airflow/operators/python.py", line 175, in execute
    return_value = self.execute_callable()
  File "/usr/local/python/3.10.13/lib/python3.10/site-packages/airflow/operators/python.py", line 192, in execute_callable
    return self.python_callable(*self.op_args, **self.op_kwargs)
  File "/workspaces/hands-on-introduction-data-engineering-4395021/airflow/dags/challenge_dag.py", line 23, in transformData
    aggregate_df = df.groupby("Sector").count()
  File "/home/codespace/.local/lib/python3.10/site-packages/pandas/core/frame.py", line 9170, in groupby
    return DataFrameGroupBy(
  File "/home/codespace/.local/lib/python3.10/site-packages/pandas/core/groupby/groupby.py", line 1329, in __init__
    grouper, exclusions, obj = get_grouper(
  File "/home/codespace/.local/lib/python3.10/site-packages/pandas/core/groupby/grouper.py", line 1043, in get_grouper
    raise KeyError(gpr)
KeyError: 'Sector'
[2024-04-13T14:44:14.139+0000] {taskinstance.py:1318} INFO - Marking task as FAILED. dag_id=challenge_dag, task_id=transform_task, execution_date=20240413T144408, start_date=20240413T144413, end_date=20240413T144414
[2024-04-13T14:44:14.166+0000] {standard_task_runner.py:100} ERROR - Failed to execute job 30 for task transform_task ('Sector'; 20188)
[2024-04-13T14:44:14.209+0000] {local_task_job.py:208} INFO - Task exited with return code 1
[2024-04-13T14:44:14.222+0000] {taskinstance.py:2578} INFO - 0 downstream tasks scheduled from follow-on schedule check
